Workbook

Sheet 工作进度总控
A1: 大疆安徽平台公关项目 · 工作进度总控表（可量化·可跟踪）
A2: 序号 | B2: 板块 | C2: 工作项 | D2: 类型/层级 | E2: 优先级 | F2: 量化目标 | G2: 计划开启 | H2: 计划闭环 | I2: 当前进度% | J2: 阶段状态 | K2: 里程碑阶段 | L2: 下一步动作 | M2: 负责人 | N2: 数据来源
A3: ▍政府关系（12 项）
A4: 1 | B4: 政府关系 | C4: 安徽省农业农村厅 | D4: 省级 | E4: A级 | F4: 推广计划、飞防作业监管 | G4: 2月 | H4: 6月 | I4: 0 | J4: 待启动 | K4: M1·未启动 | L4: 启动首次对接沟通，推进待办事项 | N4: 政府关系建立
A5: 2 | B5: 政府关系 | C5: 安徽省农业农村厅 | D5: 省级 | E5: A级 | F5: 病虫害防治、飞防作业指导 | G5: 2月 | H5: 6月 | I5: 0 | J5: 待启动 | K5: M1·未启动 | L5: 启动首次对接沟通，推进待办事项 | N5: 政府关系建立
A6: 3 | B6: 政府关系 | C6: 安徽省农业农村厅 | D6: 省级 | E6: B级 | F6: 农机监管、飞行规范 | G6: 3月 | H6: 9月 | I6: 0 | J6: 待启动 | K6: M1·未启动 | L6: 启动首次对接沟通，推进待办事项 | N6: 政府关系建立
A7: 4 | B7: 政府关系 | C7: 安徽省科技厅 | D7: 省级 | E7: A级 | F7: 科技攻关项目、智慧农业示范、产学研合作 | G7: 2月 | H7: 6月 | I7: 0 | J7: 待启动 | K7: M1·未启动 | L7: 启动首次对接沟通，推进待办事项 | N7: 政府关系建立
A8: 5 | B8: 政府关系 | C8: 安徽省发展改革委 | D8: 省级 | E8: B级 | F8: 数字乡村、高标准农田、产业政策 | G8: 5月 | H8: 11月 | I8: 0 | J8: 待启动 | K8: M1·未启动 | L8: 启动首次对接沟通，推进待办事项 | N8: 政府关系建立
A9: 6 | B9: 政府关系 | C9: 阜阳市农业农村局 | D9: 地市级 | E9: A级 | F9: 皖北小麦飞防推广、演示会、作业补贴 | G9: 2月 | H9: 5月 | I9: 0 | J9: 待启动 | K9: M1·未启动 | L9: 启动首次对接沟通，推进待办事项 | N9: 政府关系建立
A10: 7 | B10: 政府关系 | C10: 亳州市农业农村局 | D10: 地市级 | E10: A级 | F10: 皖北小麦飞防推广、作业补贴 | G10: 2月 | H10: 5月 | I10: 0 | J10: 待启动 | K10: M1·未启动 | L10: 启动首次对接沟通，推进待办事项 | N10: 政府关系建立
A11: 8 | B11: 政府关系 | C11: 宿州市农业农村局 | D11: 地市级 | E11: A级 | F11: 皖北小麦飞防推广、演示会 | G11: 2月 | H11: 5月 | I11: 0 | J11: 待启动 | K11: M1·未启动 | L11: 启动首次对接沟通，推进待办事项 | N11: 政府关系建立
A12: 9 | B12: 政府关系 | C12: 淮北市农业农村局 | D12: 地市级 | E12: B级 | F12: 皖北小麦飞防推广 | G12: 3月 | H12: 6月 | I12: 0 | J12: 待启动 | K12: M1·未启动 | L12: 启动首次对接沟通，推进待办事项 | N12: 政府关系建立
A13: 10 | B13: 政府关系 | C13: 合肥市农业农村局 | D13: 地市级 | E13: B级 | F13: 智慧农业示范、省级部门联动 | G13: 3月 | H13: 8月 | I13: 0 | J13: 待启动 | K13: M1·未启动 | L13: 启动首次对接沟通，推进待办事项 | N13: 政府关系建立
A14: 11 | B14: 政府关系 | C14: 滁州市农业农村局 | D14: 地市级 | E14: B级 | F14: 江淮水稻区推广 | G14: 4月 | H14: 7月 | I14: 0 | J14: 待启动 | K14: M1·未启动 | L14: 启动首次对接沟通，推进待办事项 | N14: 政府关系建立
A15: 12 | B15: 政府关系 | C15: 淮南市农业农村局 | D15: 地市级 | E15: B级 | F15: 江淮水稻区推广、沿淮农业 | G15: 4月 | H15: 7月 | I15: 0 | J15: 待启动 | K15: M1·未启动 | L15: 启动首次对接沟通，推进待办事项 | N15: 政府关系建立
B16: 小计：12 项 · 已完成 0 项
A17: ▍行业资源（11 项）
A18: 13 | B18: 行业资源 | C18: 安徽省农业机械工业协会 | D18: 行业协会 | E18: A级 | F18: 标准制定、行业论坛、会员资源对接 | G18: 2月 | H18: 8月 | I18: 0 | J18: 待启动 | K18: M1·未启动 | L18: 建立联系，对接合作方向 | N18: 行业资源开发
A19: 14 | B19: 行业资源 | C19: 安徽省植物保护学会 | D19: 行业协会 | E19: B级 | F19: 植保技术交流、飞防效果评估、专家资源 | G19: 3月 | H19: 9月 | I19: 0 | J19: 待启动 | K19: M1·未启动 | L19: 建立联系，对接合作方向 | N19: 行业资源开发
A20: 15 | B20: 行业资源 | C20: 安徽省农业产业联合会 | D20: 行业协会 | E20: B级 | F20: 产业资源对接、品牌活动、会员渠道 | G20: 4月 | H20: 10月 | I20: 0 | J20: 待启动 | K20: M1·未启动 | L20: 建立联系，对接合作方向 | N20: 行业资源开发
A21: 16 | B21: 行业资源 | C21: 安徽农业大学工学院 | D21: 科研院所 | E21: A级 | F21: 产学研合作、技术示范、联合申报、飞手培训 | G21: 2月 | H21: 7月 | I21: 0 | J21: 待启动 | K21: M1·未启动 | L21: 建立联系，对接合作方向 | N21: 行业资源开发
A22: 17 | B22: 行业资源 | C22: 安徽农业大学植保学院 | D22: 科研院所 | E22: B级 | F22: 植保技术研究、作业效果验证、专家顾问 | G22: 3月 | H22: 8月 | I22: 0 | J22: 待启动 | K22: M1·未启动 | L22: 建立联系，对接合作方向 | N22: 行业资源开发
A23: 18 | B23: 行业资源 | C23: 安徽省农业科学院 | D23: 科研院所 | E23: B级 | F23: 植保技术研究、作物方案定制、示范基地 | G23: 3月 | H23: 9月 | I23: 0 | J23: 待启动 | K23: M1·未启动 | L23: 建立联系，对接合作方向 | N23: 行业资源开发
A24: 19 | B24: 行业资源 | C24: 中科院合肥物质科学研究院 | D24: 科研院所 | E24: C级 | F24: 智慧农业技术、遥感监测、前沿技术合作 | G24: 6月 | H24: 12月 | I24: 0 | J24: 待启动 | K24: M1·未启动 | L24: 建立联系，对接合作方向 | N24: 行业资源开发
A25: 20 | B25: 行业资源 | C25: 安徽省农机推广总站 | D25: 推广机构 | E25: A级 | F25: 技术推广、演示会协办、作业效果评估、补贴推荐 | G25: 2月 | H25: 6月 | I25: 0 | J25: 待启动 | K25: M1·未启动 | L25: 建立联系，对接合作方向 | N25: 行业资源开发
A26: 21 | B26: 行业资源 | C26: 安徽省植保总站 | D26: 推广机构 | E26: B级 | F26: 病虫害防治指导、飞防作业规范、统防统治对接 | G26: 3月 | H26: 8月 | I26: 0 | J26: 待启动 | K26: M1·未启动 | L26: 建立联系，对接合作方向 | N26: 行业资源开发
A27: 22 | B27: 行业资源 | C27: 安徽省农民合作社联合会 | D27: 合作社联盟 | E27: B级 | F27: 批量采购、飞防服务合作、会员资源、数据采集 | G27: 4月 | H27: 10月 | I27: 0 | J27: 待启动 | K27: M1·未启动 | L27: 建立联系，对接合作方向 | N27: 行业资源开发
A28: 23 | B28: 行业资源 | C28: 全省专业飞防服务队（核心） | D28: 飞防服务 | E28: B级 | F28: 设备采购、作业服务、生态合作、数据反馈 | G28: 3月 | H28: 11月 | I28: 0 | J28: 待启动 | K28: M1·未启动 | L28: 建立联系，对接合作方向 | N28: 行业资源开发
B29: 小计：11 项 · 已完成 0 项
A30: ▍媒体传播（14 项）
A31: 24 | B31: 媒体传播 | C31: 安徽日报 | D31: 省级主流 | E31: A级 | F31: 春耕飞防作业纪实、智慧农业案例 | G31: 2月 | H31: 3月 | I31: 0 | J31: 待启动 | K31: M1·未启动 | L31: 对接选题，准备稿件/素材 | N31: 媒体品牌传播
A32: 25 | B32: 媒体传播 | C32: 安徽日报 | D32: 省级主流 | E32: A级 | F32: 秋收飞防保障、农业现代化专题 | G32: 9月 | H32: 10月 | I32: 0 | J32: 待启动 | K32: M1·未启动 | L32: 对接选题，准备稿件/素材 | N32: 媒体品牌传播
A33: 26 | B33: 媒体传播 | C33: 安徽卫视 | D33: 省级主流 | E33: B级 | F33: 飞防作业视频报道、活动现场采访 | G33: 2月 | H33: 3月 | I33: 0 | J33: 待启动 | K33: M1·未启动 | L33: 对接选题，准备稿件/素材 | N33: 媒体品牌传播
A34: 27 | B34: 媒体传播 | C34: 新安晚报 | D34: 省级主流 | E34: B级 | F34: 本地化民生视角、农户故事 | G34: 4月 | H34: 5月 | I34: 0 | J34: 待启动 | K34: M1·未启动 | L34: 对接选题，准备稿件/素材 | N34: 媒体品牌传播
A35: 28 | B35: 媒体传播 | C35: 中安在线 | D35: 省级主流 | E35: B级 | F35: 网络专题、短视频、直播 | G35: 8月 | H35: 9月 | I35: 0 | J35: 待启动 | K35: M1·未启动 | L35: 对接选题，准备稿件/素材 | N35: 媒体品牌传播
A36: 29 | B36: 媒体传播 | C36: 农民日报安徽记者站 | D36: 农业行业 | E36: A级 | F36: 行业深度报道、政策解读、案例分享 | G36: 2月 | H36: 3月 | I36: 0 | J36: 待启动 | K36: M1·未启动 | L36: 对接选题，准备稿件/素材 | N36: 媒体品牌传播
A37: 30 | B37: 媒体传播 | C37: 农民日报安徽记者站 | D37: 农业行业 | E37: A级 | F37: 秋收专题、智慧农业深度 | G37: 9月 | H37: 10月 | I37: 0 | J37: 待启动 | K37: M1·未启动 | L37: 对接选题，准备稿件/素材 | N37: 媒体品牌传播
A38: 31 | B38: 媒体传播 | C38: 农机360网 | D38: 农业行业 | E38: B级 | F38: 产品评测、行业分析、展会直播 | G38: 8月 | H38: 9月 | I38: 0 | J38: 待启动 | K38: M1·未启动 | L38: 对接选题，准备稿件/素材 | N38: 媒体品牌传播
A39: 32 | B39: 媒体传播 | C39: 农业机械杂志 | D39: 农业行业 | E39: B级 | F39: 技术文章、案例深度报道 | G39: 5月 | H39: 6月 | I39: 0 | J39: 待启动 | K39: M1·未启动 | L39: 对接选题，准备稿件/素材 | N39: 媒体品牌传播
A40: 33 | B40: 媒体传播 | C40: 中国农机推广网 | D40: 农业行业 | E40: C级 | F40: 推广信息、作业数据、政策动态 | G40: 持续 | H40: 12月 | I40: 0 | J40: 待启动 | K40: M1·未启动 | L40: 对接选题，准备稿件/素材 | N40: 媒体品牌传播
...

Sheet 年度KPI总览
A1: 指标类别 | B1: 具体指标 | C1: 年度目标 | D1: 当前完成(自动统计) | E1: 完成率 | F1: 状态 | G1: 数据来源 | H1: 备注
A2: 政府关系 | B2: 已对接政府对象数 | C2: 10 | D2: ==COUNTIF(政府关系建立!P:P,"跟进中")+COUNTIF(政府关系建立!P:P,"深度合作")+COUNTIF(政府关系建立!P:P,"已完成") -> 0 | E2: ==IF(OR(C2="",D2=""),"",IF(ISNUMBER(C2),D2/C2,"")) -> 0 | F2: ==IF(E2="","待启动",IF(E2>=1,"已完成",IF(E2>=0.5,"进行中","推进中"))) -> 推进中 | G2: 政府关系建立 | H2: 含省级+地市级
A3: 政府关系 | B3: 政府关系对象总数 | C3: 12 | D3: ==COUNTA(政府关系建立!C2:C199) -> 12 | E3: ==IF(OR(C3="",D3=""),"",IF(ISNUMBER(C3),D3/C3,"")) -> 1 | F3: ==IF(E3="","待启动",IF(E3>=1,"已完成",IF(E3>=0.5,"进行中","推进中"))) -> 已完成 | G3: 政府关系建立 | H3: 建档总数
A4: 行业资源 | B4: 已合作行业/科研对象 | C4: 5 | D4: ==COUNTIF(行业资源开发!M:M,"跟进中")+COUNTIF(行业资源开发!M:M,"深度合作")+COUNTIF(行业资源开发!M:M,"已完成") -> 0 | E4: ==IF(OR(C4="",D4=""),"",IF(ISNUMBER(C4),D4/C4,"")) -> 0 | F4: ==IF(E4="","待启动",IF(E4>=1,"已完成",IF(E4>=0.5,"进行中","推进中"))) -> 推进中 | G4: 行业资源开发 | H4: 协会+科研+推广
A5: 媒体传播 | B5: 已发布报道篇数 | C5: 15 | D5: ==COUNTIF(媒体品牌传播!N:N,"已发布") -> 0 | E5: ==IF(OR(C5="",D5=""),"",IF(ISNUMBER(C5),D5/C5,"")) -> 0 | F5: ==IF(E5="","待启动",IF(E5>=1,"已完成",IF(E5>=0.5,"进行中","推进中"))) -> 推进中 | G5: 媒体品牌传播 | H5: 省级+行业媒体
A6: 活动执行 | B6: 已完成活动场次 | C6: 8 | D6: ==COUNTIF(活动执行管理!L:L,"已完成") -> 0 | E6: ==IF(OR(C6="",D6=""),"",IF(ISNUMBER(C6),D6/C6,"")) -> 0 | F6: ==IF(E6="","待启动",IF(E6>=1,"已完成",IF(E6>=0.5,"进行中","推进中"))) -> 推进中 | G6: 活动执行管理 | H6: 含培训/沙龙/展会
A7: 活动执行 | B7: 活动总场次 | C7: 10 | D7: ==COUNTA(活动执行管理!B2:B199) -> 10 | E7: ==IF(OR(C7="",D7=""),"",IF(ISNUMBER(C7),D7/C7,"")) -> 1 | F7: ==IF(E7="","待启动",IF(E7>=1,"已完成",IF(E7>=0.5,"进行中","推进中"))) -> 已完成 | G7: 活动执行管理 | H7: 全年计划
A8: 客户转化 | B8: 已成交客户数 | C8: 5 | D8: ==COUNTIF(客户线索转化!Q:Q,"已成交") -> 0 | E8: ==IF(OR(C8="",D8=""),"",IF(ISNUMBER(C8),D8/C8,"")) -> 0 | F8: ==IF(E8="","待启动",IF(E8>=1,"已完成",IF(E8>=0.5,"进行中","推进中"))) -> 推进中 | G8: 客户线索转化 | H8: 需销售确认
A9: 客户转化 | B9: 客户线索总数 | C9: 9 | D9: ==COUNTA(客户线索转化!B3:B197) -> 9 | E9: ==IF(OR(C9="",D9=""),"",IF(ISNUMBER(C9),D9/C9,"")) -> 1 | F9: ==IF(E9="","待启动",IF(E9>=1,"已完成",IF(E9>=0.5,"进行中","推进中"))) -> 已完成 | G9: 客户线索转化 | H9: 建档总数
A10: 政策项目 | B10: 已立项项目数 | C10: 2 | D10: ==COUNTIF(政策项目申报!N:N,"已立项")+COUNTIF(政策项目申报!N:N,"已拨款") -> 0 | E10: ==IF(OR(C10="",D10=""),"",IF(ISNUMBER(C10),D10/C10,"")) -> 0 | F10: ==IF(E10="","待启动",IF(E10>=1,"已完成",IF(E10>=0.5,"进行中","推进中"))) -> 推进中 | G10: 政策项目申报 | H10: 含省级示范≥1个
A11: 政策项目 | B11: 政策项目总数 | C11: 6 | D11: ==COUNTA(政策项目申报!B2:B200) -> 8 | E11: ==IF(OR(C11="",D11=""),"",IF(ISNUMBER(C11),D11/C11,"")) -> 1.3333333 | F11: ==IF(E11="","待启动",IF(E11>=1,"已完成",IF(E11>=0.5,"进行中","推进中"))) -> 已完成 | G11: 政策项目申报 | H11: 全年申报计划

Sheet 政府关系建立
A1: 序号 | B1: 层级 | C1: 单位名称 | D1: 对接部门 | E1: 关键联系人 | F1: 职务 | G1: 联系方式 | H1: 优先级 | I1: 区域 | J1: 计划开启时间 | K1: 闭环时间 | L1: 累计联系次数 | M1: 沟通深度 | N1: 合作/待办事项 | O1: 当前进度% | P1: 状态 | Q1: 批次进度描述 | R1: 下次计划日期 | S1: 备注 | T1: 负责人 | U1: 里程碑阶段 | V1: 下一步动作
A2: 1 | B2: 省级 | C2: 安徽省农业农村厅 | D2: 农机推广总站 | H2: A级 | I2: 合肥 | J2: 2月 | K2: 6月 | L2: 0 | M2: 初步接触 | N2: 推广计划、飞防作业监管 | O2: 0 | P2: ==IF(O2=0,"待启动",IF(O2>=1,"已完成",IF(O2>=0.5,"进行中","推进中"))) -> 待启动 | Q2: 3月 | U2: M1 · 未启动 | V2: 启动首次对接沟通，推进待办事项
A3: 2 | B3: 省级 | C3: 安徽省农业农村厅 | D3: 种植业局 | H3: A级 | I3: 合肥 | J3: 2月 | K3: 6月 | L3: 0 | M3: 初步接触 | N3: 病虫害防治、飞防作业指导 | O3: 0 | P3: ==IF(O3=0,"待启动",IF(O3>=1,"已完成",IF(O3>=0.5,"进行中","推进中"))) -> 待启动 | Q3: 3月 | U3: M1 · 未启动 | V3: 启动首次对接沟通，推进待办事项
A4: 3 | B4: 省级 | C4: 安徽省农业农村厅 | D4: 农机管理处 | H4: B级 | I4: 合肥 | J4: 3月 | K4: 9月 | L4: 0 | M4: 初步接触 | N4: 农机监管、飞行规范 | O4: 0 | P4: ==IF(O4=0,"待启动",IF(O4>=1,"已完成",IF(O4>=0.5,"进行中","推进中"))) -> 待启动 | Q4: 5月 | U4: M1 · 未启动 | V4: 启动首次对接沟通，推进待办事项
A5: 4 | B5: 省级 | C5: 安徽省科技厅 | D5: 农村科技处 | H5: A级 | I5: 合肥 | J5: 2月 | K5: 6月 | L5: 0 | M5: 初步接触 | N5: 科技攻关项目、智慧农业示范、产学研合作 | O5: 0 | P5: ==IF(O5=0,"待启动",IF(O5>=1,"已完成",IF(O5>=0.5,"进行中","推进中"))) -> 待启动 | Q5: 3月 | U5: M1 · 未启动 | V5: 启动首次对接沟通，推进待办事项
A6: 5 | B6: 省级 | C6: 安徽省发展改革委 | D6: 农村经济处 | H6: B级 | I6: 合肥 | J6: 5月 | K6: 11月 | L6: 0 | M6: 初步接触 | N6: 数字乡村、高标准农田、产业政策 | O6: 0 | P6: ==IF(O6=0,"待启动",IF(O6>=1,"已完成",IF(O6>=0.5,"进行中","推进中"))) -> 待启动 | Q6: 7月 | U6: M1 · 未启动 | V6: 启动首次对接沟通，推进待办事项
A7: 6 | B7: 地市级 | C7: 阜阳市农业农村局 | D7: 农机推广站 | H7: A级 | I7: 阜阳 | J7: 2月 | K7: 5月 | L7: 0 | M7: 初步接触 | N7: 皖北小麦飞防推广、演示会、作业补贴 | O7: 0 | P7: ==IF(O7=0,"待启动",IF(O7>=1,"已完成",IF(O7>=0.5,"进行中","推进中"))) -> 待启动 | Q7: 3月 | U7: M1 · 未启动 | V7: 启动首次对接沟通，推进待办事项
A8: 7 | B8: 地市级 | C8: 亳州市农业农村局 | D8: 农机推广站 | H8: A级 | I8: 亳州 | J8: 2月 | K8: 5月 | L8: 0 | M8: 初步接触 | N8: 皖北小麦飞防推广、作业补贴 | O8: 0 | P8: ==IF(O8=0,"待启动",IF(O8>=1,"已完成",IF(O8>=0.5,"进行中","推进中"))) -> 待启动 | Q8: 3月 | U8: M1 · 未启动 | V8: 启动首次对接沟通，推进待办事项
A9: 8 | B9: 地市级 | C9: 宿州市农业农村局 | D9: 农机推广站 | H9: A级 | I9: 宿州 | J9: 2月 | K9: 5月 | L9: 0 | M9: 初步接触 | N9: 皖北小麦飞防推广、演示会 | O9: 0 | P9: ==IF(O9=0,"待启动",IF(O9>=1,"已完成",IF(O9>=0.5,"进行中","推进中"))) -> 待启动 | Q9: 3月 | U9: M1 · 未启动 | V9: 启动首次对接沟通，推进待办事项
A10: 9 | B10: 地市级 | C10: 淮北市农业农村局 | D10: 农机推广站 | H10: B级 | I10: 淮北 | J10: 3月 | K10: 6月 | L10: 0 | M10: 初步接触 | N10: 皖北小麦飞防推广 | O10: 0 | P10: ==IF(O10=0,"待启动",IF(O10>=1,"已完成",IF(O10>=0.5,"进行中","推进中"))) -> 待启动 | Q10: 4月 | U10: M1 · 未启动 | V10: 启动首次对接沟通，推进待办事项
A11: 10 | B11: 地市级 | C11: 合肥市农业农村局 | D11: 农机处 | H11: B级 | I11: 合肥 | J11: 3月 | K11: 8月 | L11: 0 | M11: 初步接触 | N11: 智慧农业示范、省级部门联动 | O11: 0 | P11: ==IF(O11=0,"待启动",IF(O11>=1,"已完成",IF(O11>=0.5,"进行中","推进中"))) -> 待启动 | Q11: 5月 | U11: M1 · 未启动 | V11: 启动首次对接沟通，推进待办事项
A12: 11 | B12: 地市级 | C12: 滁州市农业农村局 | D12: 农机推广站 | H12: B级 | I12: 滁州 | J12: 4月 | K12: 7月 | L12: 0 | M12: 初步接触 | N12: 江淮水稻区推广 | O12: 0 | P12: ==IF(O12=0,"待启动",IF(O12>=1,"已完成",IF(O12>=0.5,"进行中","推进中"))) -> 待启动 | Q12: 5月 | U12: M1 · 未启动 | V12: 启动首次对接沟通，推进待办事项
A13: 12 | B13: 地市级 | C13: 淮南市农业农村局 | D13: 农机推广站 | H13: B级 | I13: 淮南 | J13: 4月 | K13: 7月 | L13: 0 | M13: 初步接触 | N13: 江淮水稻区推广、沿淮农业 | O13: 0 | P13: ==IF(O13=0,"待启动",IF(O13>=1,"已完成",IF(O13>=0.5,"进行中","推进中"))) -> 待启动 | Q13: 5月 | U13: M1 · 未启动 | V13: 启动首次对接沟通，推进待办事项

Sheet 行业资源开发
A1: 序号 | B1: 类别 | C1: 单位名称 | D1: 关键联系人 | E1: 职务 | F1: 联系方式 | G1: 优先级 | H1: 合作方向 | I1: 计划开启时间 | J1: 闭环时间 | K1: 累计联系次数 | L1: 当前进度% | M1: 状态 | N1: 批次进度描述 | O1: 下次计划日期 | P1: 备注 | Q1: 负责人 | R1: 里程碑阶段 | S1: 下一步动作
A2: 1 | B2: 行业协会 | C2: 安徽省农业机械工业协会 | G2: A级 | H2: 标准制定、行业论坛、会员资源对接 | I2: 2月 | J2: 8月 | K2: 0 | L2: 0 | M2: ==IF(L2=0,"待启动",IF(L2>=1,"已完成",IF(L2>=0.5,"进行中","推进中"))) -> 待启动 | R2: M1 · 未启动 | S2: 建立联系，对接合作方向
A3: 2 | B3: 行业协会 | C3: 安徽省植物保护学会 | G3: B级 | H3: 植保技术交流、飞防效果评估、专家资源 | I3: 3月 | J3: 9月 | K3: 0 | L3: 0 | M3: ==IF(L3=0,"待启动",IF(L3>=1,"已完成",IF(L3>=0.5,"进行中","推进中"))) -> 待启动 | R3: M1 · 未启动 | S3: 建立联系，对接合作方向
A4: 3 | B4: 行业协会 | C4: 安徽省农业产业联合会 | G4: B级 | H4: 产业资源对接、品牌活动、会员渠道 | I4: 4月 | J4: 10月 | K4: 0 | L4: 0 | M4: ==IF(L4=0,"待启动",IF(L4>=1,"已完成",IF(L4>=0.5,"进行中","推进中"))) -> 待启动 | R4: M1 · 未启动 | S4: 建立联系，对接合作方向
A5: 4 | B5: 科研院所 | C5: 安徽农业大学工学院 | G5: A级 | H5: 产学研合作、技术示范、联合申报、飞手培训 | I5: 2月 | J5: 7月 | K5: 0 | L5: 0 | M5: ==IF(L5=0,"待启动",IF(L5>=1,"已完成",IF(L5>=0.5,"进行中","推进中"))) -> 待启动 | R5: M1 · 未启动 | S5: 建立联系，对接合作方向
A6: 5 | B6: 科研院所 | C6: 安徽农业大学植保学院 | G6: B级 | H6: 植保技术研究、作业效果验证、专家顾问 | I6: 3月 | J6: 8月 | K6: 0 | L6: 0 | M6: ==IF(L6=0,"待启动",IF(L6>=1,"已完成",IF(L6>=0.5,"进行中","推进中"))) -> 待启动 | R6: M1 · 未启动 | S6: 建立联系，对接合作方向
A7: 6 | B7: 科研院所 | C7: 安徽省农业科学院 | G7: B级 | H7: 植保技术研究、作物方案定制、示范基地 | I7: 3月 | J7: 9月 | K7: 0 | L7: 0 | M7: ==IF(L7=0,"待启动",IF(L7>=1,"已完成",IF(L7>=0.5,"进行中","推进中"))) -> 待启动 | R7: M1 · 未启动 | S7: 建立联系，对接合作方向
A8: 7 | B8: 科研院所 | C8: 中科院合肥物质科学研究院 | G8: C级 | H8: 智慧农业技术、遥感监测、前沿技术合作 | I8: 6月 | J8: 12月 | K8: 0 | L8: 0 | M8: ==IF(L8=0,"待启动",IF(L8>=1,"已完成",IF(L8>=0.5,"进行中","推进中"))) -> 待启动 | R8: M1 · 未启动 | S8: 建立联系，对接合作方向
A9: 8 | B9: 推广机构 | C9: 安徽省农机推广总站 | G9: A级 | H9: 技术推广、演示会协办、作业效果评估、补贴推荐 | I9: 2月 | J9: 6月 | K9: 0 | L9: 0 | M9: ==IF(L9=0,"待启动",IF(L9>=1,"已完成",IF(L9>=0.5,"进行中","推进中"))) -> 待启动 | R9: M1 · 未启动 | S9: 建立联系，对接合作方向
A10: 9 | B10: 推广机构 | C10: 安徽省植保总站 | G10: B级 | H10: 病虫害防治指导、飞防作业规范、统防统治对接 | I10: 3月 | J10: 8月 | K10: 0 | L10: 0 | M10: ==IF(L10=0,"待启动",IF(L10>=1,"已完成",IF(L10>=0.5,"进行中","推进中"))) -> 待启动 | R10: M1 · 未启动 | S10: 建立联系，对接合作方向
A11: 10 | B11: 合作社联盟 | C11: 安徽省农民合作社联合会 | G11: B级 | H11: 批量采购、飞防服务合作、会员资源、数据采集 | I11: 4月 | J11: 10月 | K11: 0 | L11: 0 | M11: ==IF(L11=0,"待启动",IF(L11>=1,"已完成",IF(L11>=0.5,"进行中","推进中"))) -> 待启动 | R11: M1 · 未启动 | S11: 建立联系，对接合作方向
A12: 11 | B12: 飞防服务 | C12: 全省专业飞防服务队（核心） | G12: B级 | H12: 设备采购、作业服务、生态合作、数据反馈 | I12: 3月 | J12: 11月 | K12: 0 | L12: 0 | M12: ==IF(L12=0,"待启动",IF(L12>=1,"已完成",IF(L12>=0.5,"进行中","推进中"))) -> 待启动 | R12: M1 · 未启动 | S12: 建立联系，对接合作方向

Sheet 媒体品牌传播
A1: 序号 | B1: 媒体名称 | C1: 媒体类型 | D1: 联系人 | E1: 联系方式 | F1: 优先级 | G1: 报道选题/方向 | H1: 计划开启时间 | I1: 闭环时间(计划发布) | J1: 实际发布时间 | K1: 报道链接 | L1: 曝光量/阅读量 | M1: 当前进度% | N1: 状态 | O1: 批次进度描述 | P1: 备注 | Q1: 负责人 | R1: 里程碑阶段 | S1: 下一步动作
A2: 1 | B2: 安徽日报 | C2: 省级主流 | F2: A级 | H2: 春耕飞防作业纪实、智慧农业案例 | I2: 2月 | J2: 3月 | N2: ==IF(M2=0,"待启动",IF(M2>=1,"已完成",IF(M2>=0.5,"进行中","推进中"))) -> 待启动 | R2: M1 · 未启动 | S2: 对接选题，准备稿件/素材
A3: 2 | B3: 安徽日报 | C3: 省级主流 | F3: A级 | H3: 秋收飞防保障、农业现代化专题 | I3: 9月 | J3: 10月 | N3: ==IF(M3=0,"待启动",IF(M3>=1,"已完成",IF(M3>=0.5,"进行中","推进中"))) -> 待启动 | R3: M1 · 未启动 | S3: 对接选题，准备稿件/素材
A4: 3 | B4: 安徽卫视 | C4: 省级主流 | F4: B级 | H4: 飞防作业视频报道、活动现场采访 | I4: 2月 | J4: 3月 | N4: ==IF(M4=0,"待启动",IF(M4>=1,"已完成",IF(M4>=0.5,"进行中","推进中"))) -> 待启动 | R4: M1 · 未启动 | S4: 对接选题，准备稿件/素材
A5: 4 | B5: 新安晚报 | C5: 省级主流 | F5: B级 | H5: 本地化民生视角、农户故事 | I5: 4月 | J5: 5月 | N5: ==IF(M5=0,"待启动",IF(M5>=1,"已完成",IF(M5>=0.5,"进行中","推进中"))) -> 待启动 | R5: M1 · 未启动 | S5: 对接选题，准备稿件/素材
A6: 5 | B6: 中安在线 | C6: 省级主流 | F6: B级 | H6: 网络专题、短视频、直播 | I6: 8月 | J6: 9月 | N6: ==IF(M6=0,"待启动",IF(M6>=1,"已完成",IF(M6>=0.5,"进行中","推进中"))) -> 待启动 | P6: 农交会 | R6: M1 · 未启动 | S6: 对接选题，准备稿件/素材
A7: 6 | B7: 农民日报安徽记者站 | C7: 农业行业 | F7: A级 | H7: 行业深度报道、政策解读、案例分享 | I7: 2月 | J7: 3月 | N7: ==IF(M7=0,"待启动",IF(M7>=1,"已完成",IF(M7>=0.5,"进行中","推进中"))) -> 待启动 | R7: M1 · 未启动 | S7: 对接选题，准备稿件/素材
A8: 7 | B8: 农民日报安徽记者站 | C8: 农业行业 | F8: A级 | H8: 秋收专题、智慧农业深度 | I8: 9月 | J8: 10月 | N8: ==IF(M8=0,"待启动",IF(M8>=1,"已完成",IF(M8>=0.5,"进行中","推进中"))) -> 待启动 | R8: M1 · 未启动 | S8: 对接选题，准备稿件/素材
A9: 8 | B9: 农机360网 | C9: 农业行业 | F9: B级 | H9: 产品评测、行业分析、展会直播 | I9: 8月 | J9: 9月 | N9: ==IF(M9=0,"待启动",IF(M9>=1,"已完成",IF(M9>=0.5,"进行中","推进中"))) -> 待启动 | R9: M1 · 未启动 | S9: 对接选题，准备稿件/素材
A10: 9 | B10: 农业机械杂志 | C10: 农业行业 | F10: B级 | H10: 技术文章、案例深度报道 | I10: 5月 | J10: 6月 | N10: ==IF(M10=0,"待启动",IF(M10>=1,"已完成",IF(M10>=0.5,"进行中","推进中"))) -> 待启动 | R10: M1 · 未启动 | S10: 对接选题，准备稿件/素材
A11: 10 | B11: 中国农机推广网 | C11: 农业行业 | F11: C级 | H11: 推广信息、作业数据、政策动态 | I11: 持续 | J11: 12月 | N11: ==IF(M11=0,"待启动",IF(M11>=1,"已完成",IF(M11>=0.5,"进行中","推进中"))) -> 待启动 | R11: M1 · 未启动 | S11: 对接选题，准备稿件/素材
A12: 11 | B12: 阜阳日报 | C12: 地市媒体 | F12: B级 | H12: 皖北演示会现场报道 | I12: 2月 | J12: 3月 | N12: ==IF(M12=0,"待启动",IF(M12>=1,"已完成",IF(M12>=0.5,"进行中","推进中"))) -> 待启动 | R12: M1 · 未启动 | S12: 对接选题，准备稿件/素材
A13: 12 | B13: 亳州晚报 | C13: 地市媒体 | F13: C级 | H13: 皖北演示会现场报道 | I13: 2月 | J13: 3月 | N13: ==IF(M13=0,"待启动",IF(M13>=1,"已完成",IF(M13>=0.5,"进行中","推进中"))) -> 待启动 | R13: M1 · 未启动 | S13: 对接选题，准备稿件/素材
A14: 13 | B14: 宿州广播电视台 | C14: 地市媒体 | F14: C级 | H14: 皖北演示会视频报道 | I14: 2月 | J14: 3月 | N14: ==IF(M14=0,"待启动",IF(M14>=1,"已完成",IF(M14>=0.5,"进行中","推进中"))) -> 待启动 | R14: M1 · 未启动 | S14: 对接选题，准备稿件/素材
A15: 14 | B15: 抖音/快手农业KOL | C15: 新媒体 | F15: B级 | H15: 飞手故事、作业纪实、产品种草 | I15: 持续 | J15: 12月 | N15: ==IF(M15=0,"待启动",IF(M15>=1,"已完成",IF(M15>=0.5,"进行中","推进中"))) -> 待启动 | R15: M1 · 未启动 | S15: 对接选题，准备稿件/素材

Sheet 活动执行管理
A1: 序号 | B1: 活动名称 | C1: 活动类型 | D1: 销售季 | E1: 计划开启时间(筹备) | F1: 闭环时间(活动日) | G1: 地点 | H1: 目标人数 | I1: 量化目标 | J1: 负责人 | K1: 当前进度% | L1: 执行状态 | M1: 实际费用 | N1: 实际参与人数 | O1: 现场签约(台) | P1: 收集线索(条) | Q1: 媒体报道(篇) | R1: 批次进度描述 | S1: 效果评估 | T1: 备注 | U1: 负责人 | V1: 里程碑阶段 | W1: 下一步动作
A2: 1 | B2: 皖北小麦飞防演示会-阜阳站 | C2: 演示会 | D2: S2 | E2: 2月15日 | F2: 3月8日 | G2: 阜阳 | H2: 50 | I2: 签约≥3台，线索≥20条 | K2: 0 | L2: ==IF(K2=0,"未筹备",IF(K2>=1,"已完成",IF(K2>=0.8,"待执行",IF(K2>=0.3,"筹备中","筹备初期")))) -> 未筹备 | V2: M1 · 未启动 | W2: 启动活动筹备，锁定场地/资源
A3: 2 | B3: 皖北小麦飞防演示会-亳州站 | C3: 演示会 | D3: S2 | E3: 2月20日 | F3: 3月15日 | G3: 亳州 | H3: 40 | I3: 签约≥2台，线索≥15条 | K3: 0 | L3: ==IF(K3=0,"未筹备",IF(K3>=1,"已完成",IF(K3>=0.8,"待执行",IF(K3>=0.3,"筹备中","筹备初期")))) -> 未筹备 | V3: M1 · 未启动 | W3: 启动活动筹备，锁定场地/资源
A4: 3 | B4: 皖北小麦飞防演示会-宿州站 | C4: 演示会 | D4: S2 | E4: 2月25日 | F4: 3月22日 | G4: 宿州 | H4: 40 | I4: 签约≥2台，线索≥15条 | K4: 0 | L4: ==IF(K4=0,"未筹备",IF(K4>=1,"已完成",IF(K4>=0.8,"待执行",IF(K4>=0.3,"筹备中","筹备初期")))) -> 未筹备 | V4: M1 · 未启动 | W4: 启动活动筹备，锁定场地/资源
A5: 4 | B5: 江淮水稻飞防观摩会-滁州站 | C5: 观摩会 | D5: S2 | E5: 4月10日 | F5: 5月17日 | G5: 滁州 | H5: 50 | I5: 合作意向≥3家，线索≥20条 | K5: 0 | L5: ==IF(K5=0,"未筹备",IF(K5>=1,"已完成",IF(K5>=0.8,"待执行",IF(K5>=0.3,"筹备中","筹备初期")))) -> 未筹备 | V5: M1 · 未启动 | W5: 启动活动筹备，锁定场地/资源
A6: 5 | B6: 农业行业技术沙龙 | C6: 沙龙 | D6: S2 | E6: 4月20日 | F6: 5月25日 | G6: 合肥 | H6: 30 | I6: 行业线索≥5条，报道≥1篇 | K6: 0 | L6: ==IF(K6=0,"未筹备",IF(K6>=1,"已完成",IF(K6>=0.8,"待执行",IF(K6>=0.3,"筹备中","筹备初期")))) -> 未筹备 | V6: M1 · 未启动 | W6: 启动活动筹备，锁定场地/资源
A7: 6 | B7: 水稻飞防演示会-合肥周边 | C7: 演示会 | D7: S2 | E7: 5月10日 | F7: 6月8日 | G7: 合肥 | H7: 40 | I7: 线索≥15条，体验≥20人 | K7: 0 | L7: ==IF(K7=0,"未筹备",IF(K7>=1,"已完成",IF(K7>=0.8,"待执行",IF(K7>=0.3,"筹备中","筹备初期")))) -> 未筹备 | V7: M1 · 未启动 | W7: 启动活动筹备，锁定场地/资源
A8: 7 | B8: 飞手培训认证班 | C8: 培训 | D8: S2 | E8: 6月15日 | F8: 7月18日 | G8: 合肥 | H8: 40 | I8: 结业≥35人，取证≥30人，转化≥5台 | K8: 0 | L8: ==IF(K8=0,"未筹备",IF(K8>=1,"已完成",IF(K8>=0.8,"待执行",IF(K8>=0.3,"筹备中","筹备初期")))) -> 未筹备 | V8: M1 · 未启动 | W8: 启动活动筹备，锁定场地/资源
A9: 8 | B9: 秋收飞防演示会-皖北站1 | C9: 演示会 | D9: S3 | E9: 10月1日 | F9: 10月10日 | G9: 阜阳 | H9: 50 | I9: 签约≥3台，案例≥2个 | K9: 0 | L9: ==IF(K9=0,"未筹备",IF(K9>=1,"已完成",IF(K9>=0.8,"待执行",IF(K9>=0.3,"筹备中","筹备初期")))) -> 未筹备 | V9: M1 · 未启动 | W9: 启动活动筹备，锁定场地/资源
A10: 9 | B10: 秋收飞防演示会-皖北站2 | C10: 演示会 | D10: S3 | E10: 10月1日 | F10: 10月17日 | G10: 亳州 | H10: 40 | I10: 签约≥2台，线索≥15条 | K10: 0 | L10: ==IF(K10=0,"未筹备",IF(K10>=1,"已完成",IF(K10>=0.8,"待执行",IF(K10>=0.3,"筹备中","筹备初期")))) -> 未筹备 | V10: M1 · 未启动 | W10: 启动活动筹备，锁定场地/资源
A11: 10 | B11: 年终核心客户答谢会 | C11: 答谢会 | D11: S1 | E11: 11月1日 | F11: 12月12日 | G11: 蚌埠 | H11: 30 | I11: 满意度≥90%，转介绍意向≥5家 | K11: 0 | L11: ==IF(K11=0,"未筹备",IF(K11>=1,"已完成",IF(K11>=0.8,"待执行",IF(K11>=0.3,"筹备中","筹备初期")))) -> 未筹备 | V11: M1 · 未启动 | W11: 启动活动筹备，锁定场地/资源

Sheet 客户线索转化
A1: 序号 | B1: 客户名称 | C1: 客户类型 | D1: 区域 | E1: 联系人 | F1: 联系方式 | G1: 来源渠道 | H1: 意向等级 | I1: 计划开启时间 | J1: 闭环时间(预计成交) | K1: 首次接触日期 | L1: 最近跟进日期 | M1: 跟进次数 | N1: 需求产品 | O1: 意向数量(台) | P1: 当前进度% | Q1: 状态 | R1: 批次进度描述 | S1: 备注 | T1: 负责人 | U1: 里程碑阶段 | V1: 下一步动作
A2: 1 | B2: 1
A3: 2 | B3: 皖北大型合作社（阜阳） | C3: 合作社 | D3: 阜阳 | G3: 演示会 | H3: 高 | I3: 2月 | J3: 6月 | M3: 0 | P3: 0 | Q3: ==IF(P3=0,"待启动",IF(P3>=1,"已完成",IF(P3>=0.5,"进行中","推进中"))) -> 待启动 | U3: M1 · 未启动 | V3: 建立联系，确认采购需求
A4: 3 | B4: 皖北大型合作社（亳州） | C4: 合作社 | D4: 亳州 | G4: 演示会 | H4: 高 | I4: 2月 | J4: 6月 | M4: 0 | P4: 0 | Q4: ==IF(P4=0,"待启动",IF(P4>=1,"已完成",IF(P4>=0.5,"进行中","推进中"))) -> 待启动 | U4: M1 · 未启动 | V4: 建立联系，确认采购需求
A5: 4 | B5: 皖北大型合作社（宿州） | C5: 合作社 | D5: 宿州 | G5: 演示会 | H5: 中 | I5: 2月 | J5: 7月 | M5: 0 | P5: 0 | Q5: ==IF(P5=0,"待启动",IF(P5>=1,"已完成",IF(P5>=0.5,"进行中","推进中"))) -> 待启动 | U5: M1 · 未启动 | V5: 建立联系，确认采购需求
A6: 5 | B6: 皖北种植大户（阜阳） | C6: 种植大户 | D6: 阜阳 | G6: 转介绍 | H6: 高 | I6: 3月 | J6: 7月 | M6: 0 | P6: 0 | Q6: ==IF(P6=0,"待启动",IF(P6>=1,"已完成",IF(P6>=0.5,"进行中","推进中"))) -> 待启动 | U6: M1 · 未启动 | V6: 建立联系，确认采购需求
A7: 6 | B7: 皖北种植大户（亳州） | C7: 种植大户 | D7: 亳州 | G7: 农机部门推荐 | H7: 中 | I7: 3月 | J7: 8月 | M7: 0 | P7: 0 | Q7: ==IF(P7=0,"待启动",IF(P7>=1,"已完成",IF(P7>=0.5,"进行中","推进中"))) -> 待启动 | U7: M1 · 未启动 | V7: 建立联系，确认采购需求
A8: 7 | B8: 江淮水稻合作社（滁州） | C8: 合作社 | D8: 滁州 | G8: 观摩会 | H8: 中 | I8: 4月 | J8: 9月 | M8: 0 | P8: 0 | Q8: ==IF(P8=0,"待启动",IF(P8>=1,"已完成",IF(P8>=0.5,"进行中","推进中"))) -> 待启动 | U8: M1 · 未启动 | V8: 建立联系，确认采购需求
A9: 8 | B9: 农资企业（皖北） | C9: 农资企业 | D9: 阜阳 | G9: 行业交流 | H9: 高 | I9: 3月 | J9: 9月 | M9: 0 | P9: 0 | Q9: ==IF(P9=0,"待启动",IF(P9>=1,"已完成",IF(P9>=0.5,"进行中","推进中"))) -> 待启动 | R9: 整体解决方案合作 | U9: M1 · 未启动 | V9: 建立联系，确认采购需求
A10: 9 | B10: 飞防服务队（皖北） | C10: 飞防服务 | D10: 阜阳 | G10: 行业协会 | H10: 高 | I10: 3月 | J10: 10月 | M10: 0 | P10: 0 | Q10: ==IF(P10=0,"待启动",IF(P10>=1,"已完成",IF(P10>=0.5,"进行中","推进中"))) -> 待启动 | R10: 批量采购+作业合作 | U10: M1 · 未启动 | V10: 建立联系，确认采购需求
A11: 10 | B11: 核心经销商（皖北） | C11: 经销商 | D11: 阜阳 | G11: 渠道联动 | H11: 高 | I11: 2月 | J11: 12月 | M11: 0 | P11: 0 | Q11: ==IF(P11=0,"待启动",IF(P11>=1,"已完成",IF(P11>=0.5,"进行中","推进中"))) -> 待启动 | R11: 联合推广+售后协同 | U11: M1 · 未启动 | V11: 建立联系，确认采购需求

Sheet 政策项目申报
A1: 序号 | B1: 项目名称 | C1: 申报部门 | D1: 项目类型 | E1: 政策依据 | F1: 计划开启时间 | G1: 闭环时间(申报截止) | H1: 材料准备进度% | I1: 提交日期 | J1: 审批状态 | K1: 立项金额(万元) | L1: 到账金额(万元) | M1: 当前进度% | N1: 状态 | O1: 批次进度描述 | P1: 负责人 | Q1: 备注 | R1: 负责人 | S1: 里程碑阶段 | T1: 下一步动作
A2: 1 | B2: 智慧农业技术装备示范项目 | C2: 省科技厅 | D2: 科技攻关 | E2: 安徽省科技攻关计划（农业领域） | F2: 3月 | G2: 6月 | H2: 0 | J2: 待申报 | M2: 0 | N2: ==IF(M2=0,"待启动",IF(M2>=1,"已完成",IF(M2>=0.5,"进行中","推进中"))) -> 待启动 | P2: 联合科研院所申报 | S2: M1 · 未启动 | T2: 启动材料准备，跟进申报窗口
A3: 2 | B3: 数字乡村建设试点项目 | C3: 省发改委/农业农村厅 | D3: 示范试点 | E3: 安徽省数字乡村发展行动计划 | F3: 5月 | G3: 9月 | H3: 0 | J3: 待申报 | M3: 0 | N3: ==IF(M3=0,"待启动",IF(M3>=1,"已完成",IF(M3>=0.5,"进行中","推进中"))) -> 待启动 | P3: 智慧农业示范基地 | S3: M1 · 未启动 | T3: 启动材料准备，跟进申报窗口
A4: 3 | B4: 高标准农田建设农机配套 | C4: 省农业农村厅 | D4: 工程配套 | E4: 安徽省高标准农田建设规划 | F4: 7月 | G4: 10月 | H4: 0 | J4: 待申报 | M4: 0 | N4: ==IF(M4=0,"待启动",IF(M4>=1,"已完成",IF(M4>=0.5,"进行中","推进中"))) -> 待启动 | P4: 飞防作业配套 | S4: M1 · 未启动 | T4: 启动材料准备，跟进申报窗口
A5: 4 | B5: 退役军人农机技能培训项目 | C5: 省退役军人事务厅 | D5: 就业培训 | E5: 安徽省退役军人就业创业扶持政策 | F5: 3月 | G5: 8月 | H5: 0 | J5: 待申报 | M5: 0 | N5: ==IF(M5=0,"待启动",IF(M5>=1,"已完成",IF(M5>=0.5,"进行中","推进中"))) -> 待启动 | P5: 飞手技能培训+就业对接 | S5: M1 · 未启动 | T5: 启动材料准备，跟进申报窗口
A6: 5 | B6: 职业院校无人机植保实训基地 | C6: 省教育厅/人社厅 | D6: 校企合作 | E6: 安徽省职业教育产教融合政策 | F6: 4月 | G6: 9月 | H6: 0 | J6: 待申报 | M6: 0 | N6: ==IF(M6=0,"待启动",IF(M6>=1,"已完成",IF(M6>=0.5,"进行中","推进中"))) -> 待启动 | P6: 专业共建+实训基地+人才输送 | S6: M1 · 未启动 | T6: 启动材料准备，跟进申报窗口
A7: 6 | B7: 高校毕业生就业见习基地 | C7: 省人社厅 | D7: 就业见习 | E7: 安徽省高校毕业生就业见习计划 | F7: 5月 | G7: 10月 | H7: 0 | J7: 待申报 | M7: 0 | N7: ==IF(M7=0,"待启动",IF(M7>=1,"已完成",IF(M7>=0.5,"进行中","推进中"))) -> 待启动 | P7: 见习岗位+补贴+人才储备 | S7: M1 · 未启动 | T7: 启动材料准备，跟进申报窗口
A8: 7 | B8: 市级智慧农业示范项目（阜阳） | C8: 阜阳市农业农村局 | D8: 示范项目 | E8: 阜阳市智慧农业发展扶持政策 | F8: 2月 | G8: 4月 | H8: 0 | J8: 待申报 | M8: 0 | N8: ==IF(M8=0,"待启动",IF(M8>=1,"已完成",IF(M8>=0.5,"进行中","推进中"))) -> 待启动 | P8: 联合当地合作社 | S8: M1 · 未启动 | T8: 启动材料准备，跟进申报窗口
A9: 8 | B9: 市级飞防作业补贴（皖北） | C9: 皖北地市农业农村局 | D9: 作业补贴 | E9: 各地市植保无人机作业补贴办法 | F9: 持续 | G9: 12月 | H9: 0 | J9: 待申报 | M9: 0 | N9: ==IF(M9=0,"待启动",IF(M9>=1,"已完成",IF(M9>=0.5,"进行中","推进中"))) -> 待启动 | P9: 阜阳/亳州/宿州 | S9: M1 · 未启动 | T9: 启动材料准备，跟进申报窗口
